Workbook

Sheet Raw Data
A1: Customer_ID | B1: Home_Market | C1: Acquisition_Channel | D1: First_Purchase_Date | E1: Last_Purchase_Date | F1: Total_Orders | G1: Total_Spend_USD | H1: Avg_Order_Value | I1: Days_Since_Last_Purchase | J1: Email_Subscribed | K1: Returns_Count
A2: GT-20181 | B2: Austin-South Congress | C2: Email | D2: 46139 | E2: 46217 | F2: 8 | G2: 776.32 | H2: 97.04 | I2: 0 | J2: N | K2: 2
A3: GT-20197 | B3: Seattle-Ballard | C3: Email | D3: 45859 | E3: 45859 | F3: 1 | G3: 155.28 | H3: 155.28 | I3: 358 | J3: Y | K3: 2
A4: GT-20199 | B4: Bend | C4: Email | D4: 46172 | E4: 46172 | F4: 1 | G4: 92.65 | H4: 92.65 | I4: 45 | J4: Y | K4: 1
A5: GT-20201 | B5: Austin-South Congress | C5: Email | D5: 45873 | E5: 45873 | F5: 1 | G5: 97.3 | H5: 97.3 | I5: 344 | J5: N | K5: 1
A6: GT-20203 | B6: Tacoma | C6: Email | D6: 45709 | E6: 45709 | F6: 1 | G6: 92.38 | H6: 92.38 | I6: 508 | J6: Y | K6: 1
A7: GT-20205 | B7: Portland-Pearl | C7: Email | D7: 45981 | E7: 45981 | F7: 1 | G7: 91.6 | H7: 91.6 | I7: 236 | J7: Y | K7: 1
A8: GT-20194 | B8: Bend | C8: Email | D8: 46145 | E8: 46145 | F8: 1 | G8: 133.13 | H8: 133.13 | I8: 72 | J8: Y | K8: 1
A9: GT-20208 | B9: Spokane | C9: Email | D9: 45537 | E9: 45537 | F9: 1 | G9: 92.04 | H9: 92.04 | I9: 680 | J9: Y | K9: 1
A10: GT-20207 | B10: Boise | C10: Email | D10: 46170 | E10: 46217 | F10: 3 | G10: 405.69 | H10: 135.23 | I10: 0 | J10: N | K10: 1
A11: GT-20186 | B11: Seattle-Cap Hill | C11: Email | D11: 45812 | E11: 46217 | F11: 4 | G11: 581.16 | H11: 145.29 | I11: 0 | J11: Y | K11: 1
A12: GT-20191 | B12: Austin-South Congress | C12: Email | D12: 45480 | E12: 45480 | F12: 1 | G12: 155.36 | H12: 155.36 | I12: 737 | J12: Y | K12: 1
A13: GT-20183 | B13: Salt Lake City | C13: Email | D13: 45644 | E13: 45993 | F13: 4 | G13: 208.72 | H13: 52.18 | I13: 224 | J13: Y | K13: 1
... A281: GT-20278 | B281: Portland-Division | C281: Walk-in | D281: 46165 | E281: 46165 | F281: 1 | G281: 110.56 | H281: 110.56 | I281: 52 | J281: Y | K281: 0

Sheet Cleaned Data
A1: Customer_ID | B1: Home_Market | C1: Acquisition_Channel | D1: First_Purchase_Date | E1: Last_Purchase_Date | F1: Total_Orders | G1: Total_Spend_USD | H1: Avg_Order_Value | I1: Days_Since_Last_Purchase | J1: Email_Subscribed | K1: Returns_Count
A2: GT-20181 | B2: Austin-South Congress | C2: Email | D2: 46139 | E2: 46217 | F2: 8 | G2: 776.32 | H2: 97.04 | I2: 0 | J2: N | K2: 2
A3: GT-20197 | B3: Seattle-Ballard | C3: Email | D3: 45859 | E3: 45859 | F3: 1 | G3: 155.28 | H3: 155.28 | I3: 358 | J3: Y | K3: 2
A4: GT-20199 | B4: Bend | C4: Email | D4: 46172 | E4: 46172 | F4: 1 | G4: 92.65 | H4: 92.65 | I4: 45 | J4: Y | K4: 1
A5: GT-20201 | B5: Austin-South Congress | C5: Email | D5: 45873 | E5: 45873 | F5: 1 | G5: 97.3 | H5: 97.3 | I5: 344 | J5: N | K5: 1
A6: GT-20203 | B6: Tacoma | C6: Email | D6: 45709 | E6: 45709 | F6: 1 | G6: 92.38 | H6: 92.38 | I6: 508 | J6: Y | K6: 1
A7: GT-20205 | B7: Portland-Pearl | C7: Email | D7: 45981 | E7: 45981 | F7: 1 | G7: 91.6 | H7: 91.6 | I7: 236 | J7: Y | K7: 1
A8: GT-20194 | B8: Bend | C8: Email | D8: 46145 | E8: 46145 | F8: 1 | G8: 133.13 | H8: 133.13 | I8: 72 | J8: Y | K8: 1
A9: GT-20208 | B9: Spokane | C9: Email | D9: 45537 | E9: 45537 | F9: 1 | G9: 92.04 | H9: 92.04 | I9: 680 | J9: Y | K9: 1
A10: GT-20207 | B10: Boise | C10: Email | D10: 46170 | E10: 46217 | F10: 3 | G10: 405.69 | H10: 135.23 | I10: 0 | J10: N | K10: 1
A11: GT-20186 | B11: Seattle-Cap Hill | C11: Email | D11: 45812 | E11: 46217 | F11: 4 | G11: 581.16 | H11: 145.29 | I11: 0 | J11: Y | K11: 1
A12: GT-20191 | B12: Austin-South Congress | C12: Email | D12: 45480 | E12: 45480 | F12: 1 | G12: 155.36 | H12: 155.36 | I12: 737 | J12: Y | K12: 1
A13: GT-20183 | B13: Salt Lake City | C13: Email | D13: 45644 | E13: 45993 | F13: 4 | G13: 208.72 | H13: 52.18 | I13: 224 | J13: Y | K13: 1
... A281: GT-20278 | B281: Portland-Division | C281: Walk-in | D281: 46165 | E281: 46165 | F281: 1 | G281: 110.56 | H281: 110.56 | I281: 52 | J281: Y | K281: 0

Sheet Email Compare

Sheet Returns

Sheet Average Spend

Sheet Repeat Customers

Sheet Customer Count by Channel

Sheet Cleaning Log
A1: Check | B1: Formula | L1: Date Check | M1: AOV Check
A2: Blank Customer IDs | B2: =COUNTBLANK('Cleaned Data'!A2:A281) -> 0 | L2: =IF('Cleaned Data'!E2<'Cleaned Data'!D2,"ERROR","OK") -> OK | M2: =IF(OR('Cleaned Data'!F2="",'Cleaned Data'!G2="",'Cleaned Data'!H2=""),"",IF('Cleaned Data'!F2=0,"CHECK",IF(ABS(('Cleaned Data'!G2/'Cleaned Data'!F2)-'Cleaned Data'!H2)<=0.01,"OK","CHECK"))) -> OK
A3: Blank Markets | B3: =COUNTBLANK('Cleaned Data'!B2:B281) -> 0 | L3: =IF('Cleaned Data'!E3<'Cleaned Data'!D3,"ERROR","OK") -> OK | M3: =IF(OR('Cleaned Data'!F3="",'Cleaned Data'!G3="",'Cleaned Data'!H3=""),"",IF('Cleaned Data'!F3=0,"CHECK",IF(ABS(('Cleaned Data'!G3/'Cleaned Data'!F3)-'Cleaned Data'!H3)<=0.01,"OK","CHECK"))) -> OK
A4: Blank Channels | B4: =COUNTBLANK('Cleaned Data'!C2:C281) -> 0 | L4: =IF('Cleaned Data'!E4<'Cleaned Data'!D4,"ERROR","OK") -> OK | M4: =IF(OR('Cleaned Data'!F4="",'Cleaned Data'!G4="",'Cleaned Data'!H4=""),"",IF('Cleaned Data'!F4=0,"CHECK",IF(ABS(('Cleaned Data'!G4/'Cleaned Data'!F4)-'Cleaned Data'!H4)<=0.01,"OK","CHECK"))) -> OK
A5: Blank First Purchase Dates | B5: =COUNTBLANK('Cleaned Data'!D2:D281) -> 0 | L5: =IF('Cleaned Data'!E5<'Cleaned Data'!D5,"ERROR","OK") -> OK | M5: =IF(OR('Cleaned Data'!F5="",'Cleaned Data'!G5="",'Cleaned Data'!H5=""),"",IF('Cleaned Data'!F5=0,"CHECK",IF(ABS(('Cleaned Data'!G5/'Cleaned Data'!F5)-'Cleaned Data'!H5)<=0.01,"OK","CHECK"))) -> OK
A6: Blank Last Purchase Dates | B6: =COUNTBLANK('Cleaned Data'!E2:E281) -> 0 | L6: =IF('Cleaned Data'!E6<'Cleaned Data'!D6,"ERROR","OK") -> OK | M6: =IF(OR('Cleaned Data'!F6="",'Cleaned Data'!G6="",'Cleaned Data'!H6=""),"",IF('Cleaned Data'!F6=0,"CHECK",IF(ABS(('Cleaned Data'!G6/'Cleaned Data'!F6)-'Cleaned Data'!H6)<=0.01,"OK","CHECK"))) -> OK
A7: Checked all 280 records for blank cells. No missing values were found, so no records needed to be removed or filled. | L7: =IF('Cleaned Data'!E7<'Cleaned Data'!D7,"ERROR","OK") -> OK | M7: =IF(OR('Cleaned Data'!F7="",'Cleaned Data'!G7="",'Cleaned Data'!H7=""),"",IF('Cleaned Data'!F7=0,"CHECK",IF(ABS(('Cleaned Data'!G7/'Cleaned Data'!F7)-'Cleaned Data'!H7)<=0.01,"OK","CHECK"))) -> OK
L8: =IF('Cleaned Data'!E8<'Cleaned Data'!D8,"ERROR","OK") -> OK | M8: =IF(OR('Cleaned Data'!F8="",'Cleaned Data'!G8="",'Cleaned Data'!H8=""),"",IF('Cleaned Data'!F8=0,"CHECK",IF(ABS(('Cleaned Data'!G8/'Cleaned Data'!F8)-'Cleaned Data'!H8)<=0.01,"OK","CHECK"))) -> OK
L9: =IF('Cleaned Data'!E9<'Cleaned Data'!D9,"ERROR","OK") -> OK | M9: =IF(OR('Cleaned Data'!F9="",'Cleaned Data'!G9="",'Cleaned Data'!H9=""),"",IF('Cleaned Data'!F9=0,"CHECK",IF(ABS(('Cleaned Data'!G9/'Cleaned Data'!F9)-'Cleaned Data'!H9)<=0.01,"OK","CHECK"))) -> OK
A10: =IFERROR(__xludf.DUMMYFUNCTION("COUNTA('Cleaned Data'!A2:A281)-COUNTUNIQUE('Cleaned Data'!A2:A281)"),0.0) -> 0 | L10: =IF('Cleaned Data'!E10<'Cleaned Data'!D10,"ERROR","OK") -> OK | M10: =IF(OR('Cleaned Data'!F10="",'Cleaned Data'!G10="",'Cleaned Data'!H10=""),"",IF('Cleaned Data'!F10=0,"CHECK",IF(ABS(('Cleaned Data'!G10/'Cleaned Data'!F10)-'Cleaned Data'!H10)<=0.01,"OK","CHECK"))) -> OK
A11: Compared the total number of Customer IDs with the number of unique IDs. No duplicate customer records were found. | L11: =IF('Cleaned Data'!E11<'Cleaned Data'!D11,"ERROR","OK") -> OK | M11: =IF(OR('Cleaned Data'!F11="",'Cleaned Data'!G11="",'Cleaned Data'!H11=""),"",IF('Cleaned Data'!F11=0,"CHECK",IF(ABS(('Cleaned Data'!G11/'Cleaned Data'!F11)-'Cleaned Data'!H11)<=0.01,"OK","CHECK"))) -> OK
L12: =IF('Cleaned Data'!E12<'Cleaned Data'!D12,"ERROR","OK") -> OK | M12: =IF(OR('Cleaned Data'!F12="",'Cleaned Data'!G12="",'Cleaned Data'!H12=""),"",IF('Cleaned Data'!F12=0,"CHECK",IF(ABS(('Cleaned Data'!G12/'Cleaned Data'!F12)-'Cleaned Data'!H12)<=0.01,"OK","CHECK"))) -> OK
A13: Orders below 1 | B13: =COUNTIF('Cleaned Data'!F2:F281,"<1") -> 0 | L13: =IF('Cleaned Data'!E13<'Cleaned Data'!D13,"ERROR","OK") -> OK | M13: =IF(OR('Cleaned Data'!F13="",'Cleaned Data'!G13="",'Cleaned Data'!H13=""),"",IF('Cleaned Data'!F13=0,"CHECK",IF(ABS(('Cleaned Data'!G13/'Cleaned Data'!F13)-'Cleaned Data'!H13)<=0.01,"OK","CHECK"))) -> OK
A14: Spending at or below $0 | B14: =COUNTIF('Cleaned Data'!G2:G281,"<=0") -> 0 | L14: =IF('Cleaned Data'!E14<'Cleaned Data'!D14,"ERROR","OK") -> OK | M14: =IF(OR('Cleaned Data'!F14="",'Cleaned Data'!G14="",'Cleaned Data'!H14=""),"",IF('Cleaned Data'!F14=0,"CHECK",IF(ABS(('Cleaned Data'!G14/'Cleaned Data'!F14)-'Cleaned Data'!H14)<=0.01,"OK","CHECK"))) -> OK
A15: Average order value at or below $0 | B15: =COUNTIF('Cleaned Data'!H2:H281,"<=0") -> 0 | L15: =IF('Cleaned Data'!E15<'Cleaned Data'!D15,"ERROR","OK") -> OK | M15: =IF(OR('Cleaned Data'!F15="",'Cleaned Data'!G15="",'Cleaned Data'!H15=""),"",IF('Cleaned Data'!F15=0,"CHECK",IF(ABS(('Cleaned Data'!G15/'Cleaned Data'!F15)-'Cleaned Data'!H15)<=0.01,"OK","CHECK"))) -> OK
A16: Negative days since purchase | B16: =COUNTIF('Cleaned Data'!I2:I281,"<0") -> 0 | L16: =IF('Cleaned Data'!E16<'Cleaned Data'!D16,"ERROR","OK") -> OK | M16: =IF(OR('Cleaned Data'!F16="",'Cleaned Data'!G16="",'Cleaned Data'!H16=""),"",IF('Cleaned Data'!F16=0,"CHECK",IF(ABS(('Cleaned Data'!G16/'Cleaned Data'!F16)-'Cleaned Data'!H16)<=0.01,"OK","CHECK"))) -> OK
A17: Negative returns | B17: =COUNTIF('Cleaned Data'!K2:K281,"<0") -> 0 | L17: =IF('Cleaned Data'!E17<'Cleaned Data'!D17,"ERROR","OK") -> OK | M17: =IF(OR('Cleaned Data'!F17="",'Cleaned Data'!G17="",'Cleaned Data'!H17=""),"",IF('Cleaned Data'!F17=0,"CHECK",IF(ABS(('Cleaned Data'!G17/'Cleaned Data'!F17)-'Cleaned Data'!H17)<=0.01,"OK","CHECK"))) -> OK
L18: =IF('Cleaned Data'!E18<'Cleaned Data'!D18,"ERROR","OK") -> OK | M18: =IF(OR('Cleaned Data'!F18="",'Cleaned Data'!G18="",'Cleaned Data'!H18=""),"",IF('Cleaned Data'!F18=0,"CHECK",IF(ABS(('Cleaned Data'!G18/'Cleaned Data'!F18)-'Cleaned Data'!H18)<=0.01,"OK","CHECK"))) -> OK
L19: =IF('Cleaned Data'!E19<'Cleaned Data'!D19,"ERROR","OK") -> OK | M19: =IF(OR('Cleaned Data'!F19="",'Cleaned Data'!G19="",'Cleaned Data'!H19=""),"",IF('Cleaned Data'!F19=0,"CHECK",IF(ABS(('Cleaned Data'!G19/'Cleaned Data'!F19)-'Cleaned Data'!H19)<=0.01,"OK","CHECK"))) -> OK
A20: no customer has a last purchase date occurring before their first purchase date. | L20: =IF('Cleaned Data'!E20<'Cleaned Data'!D20,"ERROR","OK") -> OK | M20: =IF(OR('Cleaned Data'!F20="",'Cleaned Data'!G20="",'Cleaned Data'!H20=""),"",IF('Cleaned Data'!F20=0,"CHECK",IF(ABS(('Cleaned Data'!G20/'Cleaned Data'!F20)-'Cleaned Data'!H20)<=0.01,"OK","CHECK"))) -> OK
L21: =IF('Cleaned Data'!E21<'Cleaned Data'!D21,"ERROR","OK") -> OK | M21: =IF(OR('Cleaned Data'!F21="",'Cleaned Data'!G21="",'Cleaned Data'!H21=""),"",IF('Cleaned Data'!F21=0,"CHECK",IF(ABS(('Cleaned Data'!G21/'Cleaned Data'!F21)-'Cleaned Data'!H21)<=0.01,"OK","CHECK"))) -> OK
A22: every value in Avg_Order_Value correctly equals total spending divided by total orders, within one cent. | L22: =IF('Cleaned Data'!E22<'Cleaned Data'!D22,"ERROR","OK") -> OK | M22: =IF(OR('Cleaned Data'!F22="",'Cleaned Data'!G22="",'Cleaned Data'!H22=""),"",IF('Cleaned Data'!F22=0,"CHECK",IF(ABS(('Cleaned Data'!G22/'Cleaned Data'!F22)-'Cleaned Data'!H22)<=0.01,"OK","CHECK"))) -> OK
L23: =IF('Cleaned Data'!E23<'Cleaned Data'!D23,"ERROR","OK") -> OK | M23: =IF(OR('Cleaned Data'!F23="",'Cleaned Data'!G23="",'Cleaned Data'!H23=""),"",IF('Cleaned Data'!F23=0,"CHECK",IF(ABS(('Cleaned Data'!G23/'Cleaned Data'!F23)-'Cleaned Data'!H23)<=0.01,"OK","CHECK"))) -> OK
L24: =IF('Cleaned Data'!E24<'Cleaned Data'!D24,"ERROR","OK") -> OK | M24: =IF(OR('Cleaned Data'!F24="",'Cleaned Data'!G24="",'Cleaned Data'!H24=""),"",IF('Cleaned Data'!F24=0,"CHECK",IF(ABS(('Cleaned Data'!G24/'Cleaned Data'!F24)-'Cleaned Data'!H24)<=0.01,"OK","CHECK"))) -> OK
L25: =IF('Cleaned Data'!E25<'Cleaned Data'!D25,"ERROR","OK") -> OK | M25: =IF(OR('Cleaned Data'!F25="",'Cleaned Data'!G25="",'Cleaned Data'!H25=""),"",IF('Cleaned Data'!F25=0,"CHECK",IF(ABS(('Cleaned Data'!G25/'Cleaned Data'!F25)-'Cleaned Data'!H25)<=0.01,"OK","CHECK"))) -> OK
A26: Data Cleaning and Validation: I created a separate working copy of the original Marketing B customer dataset so the raw data remained unchanged. I checked all 280 records for missing values, duplicate Customer IDs, invalid dates, nonpositive order or spending values, negative return counts, and inconsistent average order values. No missing values, duplicate customer records, invalid date sequences, or impossible numeric values were found. I also verified that Average Order Value matched Total Spend divided by Total Orders for every record. The only changes made were standardizing date, currency, and numeric formatting and adding filters for analysis. | L26: =IF('Cleaned Data'!E26<'Cleaned Data'!D26,"ERROR","OK") -> OK | M26: =IF(OR('Cleaned Data'!F26="",'Cleaned Data'!G26="",'Cleaned Data'!H26=""),"",IF('Cleaned Data'!F26=0,"CHECK",IF(ABS(('Cleaned Data'!G26/'Cleaned Data'!F26)-'Cleaned Data'!H26)<=0.01,"OK","CHECK"))) -> OK
L27: =IF('Cleaned Data'!E27<'Cleaned Data'!D27,"ERROR","OK") -> OK | M27: =IF(OR('Cleaned Data'!F27="",'Cleaned Data'!G27="",'Cleaned Data'!H27=""),"",IF('Cleaned Data'!F27=0,"CHECK",IF(ABS(('Cleaned Data'!G27/'Cleaned Data'!F27)-'Cleaned Data'!H27)<=0.01,"OK","CHECK"))) -> OK
A28: Independent Verification: The cleaned dataset was compared with the original file using Customer ID as the matching field. All 280 customer records were present, and no underlying customer values changed. Differences between the files were limited to date and currency formatting and row order. | L28: =IF('Cleaned Data'!E28<'Cleaned Data'!D28,"ERROR","OK") -> OK | M28: =IF(OR('Cleaned Data'!F28="",'Cleaned Data'!G28="",'Cleaned Data'!H28=""),"",IF('Cleaned Data'!F28=0,"CHECK",IF(ABS(('Cleaned Data'!G28/'Cleaned Data'!F28)-'Cleaned Data'!H28)<=0.01,"OK","CHECK"))) -> OK
L29: =IF('Cleaned Data'!E29<'Cleaned Data'!D29,"ERROR","OK") -> OK | M29: =IF(OR('Cleaned Data'!F29="",'Cleaned Data'!G29="",'Cleaned Data'!H29=""),"",IF('Cleaned Data'!F29=0,"CHECK",IF(ABS(('Cleaned Data'!G29/'Cleaned Data'!F29)-'Cleaned Data'!H29)<=0.01,"OK","CHECK"))) -> OK
L30: =IF('Cleaned Data'!E30<'Cleaned Data'!D30,"ERROR","OK") -> OK | M30: =IF(OR('Cleaned Data'!F30="",'Cleaned Data'!G30="",'Cleaned Data'!H30=""),"",IF('Cleaned Data'!F30=0,"CHECK",IF(ABS(('Cleaned Data'!G30/'Cleaned Data'!F30)-'Cleaned Data'!H30)<=0.01,"OK","CHECK"))) -> OK
L31: =IF('Cleaned Data'!E31<'Cleaned Data'!D31,"ERROR","OK") -> OK | M31: =IF(OR('Cleaned Data'!F31="",'Cleaned Data'!G31="",'Cleaned Data'!H31=""),"",IF('Cleaned Data'!F31=0,"CHECK",IF(ABS(('Cleaned Data'!G31/'Cleaned Data'!F31)-'Cleaned Data'!H31)<=0.01,"OK","CHECK"))) -> OK
L32: =IF('Cleaned Data'!E32<'Cleaned Data'!D32,"ERROR","OK") -> OK | M32: =IF(OR('Cleaned Data'!F32="",'Cleaned Data'!G32="",'Cleaned Data'!H32=""),"",IF('Cleaned Data'!F32=0,"CHECK",IF(ABS(('Cleaned Data'!G32/'Cleaned Data'!F32)-'Cleaned Data'!H32)<=0.01,"OK","CHECK"))) -> OK
L33: =IF('Cleaned Data'!E33<'Cleaned Data'!D33,"ERROR","OK") -> OK | M33: =IF(OR('Cleaned Data'!F33="",'Cleaned Data'!G33="",'Cleaned Data'!H33=""),"",IF('Cleaned Data'!F33=0,"CHECK",IF(ABS(('Cleaned Data'!G33/'Cleaned Data'!F33)-'Cleaned Data'!H33)<=0.01,"OK","CHECK"))) -> OK
L34: =IF('Cleaned Data'!E34<'Cleaned Data'!D34,"ERROR","OK") -> OK | M34: =IF(OR('Cleaned Data'!F34="",'Cleaned Data'!G34="",'Cleaned Data'!H34=""),"",IF('Cleaned Data'!F34=0,"CHECK",IF(ABS(('Cleaned Data'!G34/'Cleaned Data'!F34)-'Cleaned Data'!H34)<=0.01,"OK","CHECK"))) -> OK
L35: =IF('Cleaned Data'!E35<'Cleaned Data'!D35,"ERROR","OK") -> OK | M35: =IF(OR('Cleaned Data'!F35="",'Cleaned Data'!G35="",'Cleaned Data'!H35=""),"",IF('Cleaned Data'!F35=0,"CHECK",IF(ABS(('Cleaned Data'!G35/'Cleaned Data'!F35)-'Cleaned Data'!H35)<=0.01,"OK","CHECK"))) -> OK
L36: =IF('Cleaned Data'!E36<'Cleaned Data'!D36,"ERROR","OK") -> OK | M36: =IF(OR('Cleaned Data'!F36="",'Cleaned Data'!G36="",'Cleaned Data'!H36=""),"",IF('Cleaned Data'!F36=0,"CHECK",IF(ABS(('Cleaned Data'!G36/'Cleaned Data'!F36)-'Cleaned Data'!H36)<=0.01,"OK","CHECK"))) -> OK
L37: =IF('Cleaned Data'!E37<'Cleaned Data'!D37,"ERROR","OK") -> OK | M37: =IF(OR('Cleaned Data'!F37="",'Cleaned Data'!G37="",'Cleaned Data'!H37=""),"",IF('Cleaned Data'!F37=0,"CHECK",IF(ABS(('Cleaned Data'!G37/'Cleaned Data'!F37)-'Cleaned Data'!H37)<=0.01,"OK","CHECK"))) -> OK
L38: =IF('Cleaned Data'!E38<'Cleaned Data'!D38,"ERROR","OK") -> OK | M38: =IF(OR('Cleaned Data'!F38="",'Cleaned Data'!G38="",'Cleaned Data'!H38=""),"",IF('Cleaned Data'!F38=0,"CHECK",IF(ABS(('Cleaned Data'!G38/'Cleaned Data'!F38)-'Cleaned Data'!H38)<=0.01,"OK","CHECK"))) -> OK
L39: =IF('Cleaned Data'!E39<'Cleaned Data'!D39,"ERROR","OK") -> OK | M39: =IF(OR('Cleaned Data'!F39="",'Cleaned Data'!G39="",'Cleaned Data'!H39=""),"",IF('Cleaned Data'!F39=0,"CHECK",IF(ABS(('Cleaned Data'!G39/'Cleaned Data'!F39)-'Cleaned Data'!H39)<=0.01,"OK","CHECK"))) -> OK
L40: =IF('Cleaned Data'!E40<'Cleaned Data'!D40,"ERROR","OK") -> OK | M40: =IF(OR('Cleaned Data'!F40="",'Cleaned Data'!G40="",'Cleaned Data'!H40=""),"",IF('Cleaned Data'!F40=0,"CHECK",IF(ABS(('Cleaned Data'!G40/'Cleaned Data'!F40)-'Cleaned Data'!H40)<=0.01,"OK","CHECK"))) -> OK
...

Sheet Analysis
A1: Customer Demand
A2: Metric | B2: Value
A3: Total Customers | B3: 280
A4: Repeat Customers | B4: 76
A5: Repeat Customer Rate | B5: 0.271
A6: Average Orders per Customer | B6: 2.2
A7: Average Days Since Last Purchase | B7: 315.6
A10: Key Findings
A11: Finding | B11: Evidence | C11: Why it Matters for HR
A12: Customer acquisition is concentrated in a few channels | B12: Instagram has 84 customers, followed by Google Ads with 50 and Facebook with 45 | C12: HR should prepare for demand generated across several launch channels rather than relying on one source
A13: Repeat demand continues after the first purchase | B13: 76 of 280 customers, or 27.1%, placed more than one order | C13: Staffing needs continue after opening day
A14: Email subscribers show slightly stronger activity | B14: Subscribers average about 2.25 orders and $214.66 in spending, compared with 2.04 orders and $197.09 for non-subscribers | C14: Ongoing customer engagement may create steadier post-launch workload
A15: Customer activity varies by acquisition channel | B15: Email customers averaged 3.79 orders, followed by Referral customers at 3.36 and Organic customers at 3.15, compared with the overall average of about 2.19 orders | C15: HR may need flexible staffing beyond opening day because some customer groups generate more repeat demand than others
A16: Email had the highest Repeat Customers
A17: Instagram had the highest spend amount
A18: Walk in had a little bit higher return rate than the rest of the channels
A19: Customer purchasing behavior varies by acquisition channel. | B19: Email customers averaged 3.79 orders, followed by Referral customers at 3.36 and Organic customers at 3.15. Facebook customers averaged the fewest at 1.51 orders, compared with the overall average of 2.19. | C19: Some customer groups create more repeat demand than others, so HR may need flexible staffing plans instead of assuming customer activity will be the same across every channel.
A21: The analysis shows that GreenThreads attracts customers through several channels and that 27.1% of customers place repeat orders. Email subscribers also show slightly higher average orders and spending than non-subscribers. These patterns suggest that staffing needs continue after the grand opening and may change depending on how customer demand develops across acquisition channels. Because this dataset does not include hourly store traffic or staffing levels, it should support workforce planning rather than determine schedules by itself.

Sheet Choice Set
A1: Option | B1: Approach | C1: Advantages | D1: Trade-offs
A2: Current/Manual Staffing and Planning | B2: HR continues using historical experience and manager judgment to determine staffing needs. | C2: No new technology or implementation cost; managers keep full control. | D2: Reactive and does not systematically account for changes in customer demand; could lead to over- or understaffing.
A3: Demand-Informed Staffing | B3: HR reviews customer trends, historical foot traffic, transactions, and other demand indicators before managers set staffing levels. | C3: Uses actual demand data without requiring a full AI system; keeps human decision-making central. | D3: Requires someone to manually combine and interpret multiple datasets, adding workload to an already-busy HR team.
A4: AI-Assisted Staffing Forecast | B4: AI combines historical store demand, customer trends, and HR information to recommend staffing needs; managers make the final decision. | C4: Uses multiple demand signals, reduces manual analysis, and directly supports the Level 3 staffing-forecasting opportunity identified in HW#1. | D4: Requires clean, integrated data and an approved AI environment; forecasts can be wrong if historical data do not represent Denver accurately.
A6: Recommended Option | B6: Option 3 - AI Assisted Staffing Forecast
A8: Recommendation Rationale
A9: Option 3 best supports GreenThreads' staffing goal because it uses customer and historical store-demand data to reduce manual forecasting workload while keeping HR and store management responsible for final hiring and scheduling decisions.
A12: Key Limitations
A13: Historical customer and store data may not perfectly predict demand at the new Denver location. AI forecasts should therefore be used as decision support rather than automatic staffing decisions.

Sheet Supporting Evidence
A1: Source | B1: Verified Fact | C1: Why it Matters
A2: HR Offer Letter | B2: Sales Associate pay is $17.50/hour, up to 28 hours/week, with a proposed start date of September 28, 2026 | C2: Shows how close hiring and onboarding occur to launch and why earlier forecasting could help
A3: Denver Budget | B3: Staffing and recruiting budget is $65,000 | C3: Shows whether the recommendation is financially realistic
A4: Finance Transactions | B4: HR-related spending totals $17,558.56, including $13,821.44 paid and $3,737.12 pending. Recruiting and job-board spending totals $3,642.88, training totals $5,822.42, pre-opening payroll totals $6,632.80, and uniforms total $1,460.46. | C4: Shows how much of the staffing and recruiting budget has already been committed and whether GreenThreads still has room to support earlier hiring, training, or an AI-assisted staffing process.
A5: Finance Transactions | B5: Technology spending totals $6,648.72, including $6,209.04 paid and $439.68 pending. | C5: Shows that GreenThreads is already investing in systems, but the transactions do not identify a specific AI staffing tool, so any AI recommendation would still need budget approval and human oversight.
A6: Case Brief | B6: Denver needs 14 employees, with 7 seats still open | C6: Establishes the staffing gap and urgency
A8: Budget + Finance Transactions | B8: The Denver budget allocates $65,000 to staffing/recruiting and $20,000 to technology. Recorded HR spending equals about 27.0% of the staffing/recruiting budget, while recorded technology spending equals about 33.2% of the technology budget. | C8: Shows that only part of each budget has been recorded as spent, although any new AI investment would still require management approval.
